Traceback (most recent call last):
  File "/Users/jm/Library/Python/3.9/lib/python/site-packages/jupyter_cache/executors/utils.py", line 58, in single_nb_execution
    executenb(
  File "/Users/jm/Library/Python/3.9/lib/python/site-packages/nbclient/client.py", line 1319, in execute
    return NotebookClient(nb=nb, resources=resources, km=km, **kwargs).execute()
  File "/Users/jm/Library/Python/3.9/lib/python/site-packages/jupyter_core/utils/__init__.py", line 165, in wrapped
    return loop.run_until_complete(inner)
  File "/Library/Developer/CommandLineTools/Library/Frameworks/Python3.framework/Versions/3.9/lib/python3.9/asyncio/base_events.py", line 642, in run_until_complete
    return future.result()
  File "/Users/jm/Library/Python/3.9/lib/python/site-packages/nbclient/client.py", line 709, in async_execute
    await self.async_execute_cell(
  File "/Users/jm/Library/Python/3.9/lib/python/site-packages/nbclient/client.py", line 1062, in async_execute_cell
    await self._check_raise_for_error(cell, cell_index, exec_reply)
  File "/Users/jm/Library/Python/3.9/lib/python/site-packages/nbclient/client.py", line 918, in _check_raise_for_error
    raise CellExecutionError.from_cell_and_msg(cell, exec_reply_content)
nbclient.exceptions.CellExecutionError: An error occurred while executing the following cell:
------------------
# importing the required module
import matplotlib.pyplot as plt

# create data
x = list(range(10,100,10))
y1 = list(range(100,10,-10))
y2 = list(range(10,100,10))

# create plot
plt.clf() # clear the current figure if any
plt.plot(x, y1, label = "line 1") # plot lines
plt.plot(x, y2, label = "line 2") # plot lines
plt.legend() # add legend
plt.title('Relationship between x and y') # add title
plt.show() # show the plot
------------------


[0;31m---------------------------------------------------------------------------[0m
[0;31mModuleNotFoundError[0m                       Traceback (most recent call last)
Cell [0;32mIn[15], line 2[0m
[1;32m      1[0m [38;5;66;03m# importing the required module[39;00m
[0;32m----> 2[0m [38;5;28;01mimport[39;00m[38;5;250m [39m[38;5;21;01mmatplotlib[39;00m[38;5;21;01m.[39;00m[38;5;21;01mpyplot[39;00m[38;5;250m [39m[38;5;28;01mas[39;00m[38;5;250m [39m[38;5;21;01mplt[39;00m
[1;32m      4[0m [38;5;66;03m# create data[39;00m
[1;32m      5[0m x [38;5;241m=[39m [38;5;28mlist[39m([38;5;28mrange[39m([38;5;241m10[39m,[38;5;241m100[39m,[38;5;241m10[39m))

[0;31mModuleNotFoundError[0m: No module named 'matplotlib'

